Workbook

Sheet APPENDIX
B6: Musk Business Ecosystem: Financial, Strategic & Risk Analysis
B8: Project objective
B9: Conduct an independent, evidence-based assessment of Elon Musk's business ecosystem, evaluating financial performance, growth strategies, capital requirements, corporate relationships, and material risks.
B11: Research scope
B12: Tesla
B14: SpaceX and Starlink
B16: xAI and X
B18: Neuralink
B20: The Boring Company
B23: Core deliverables
B25: Individual company financial and strategic assessments.
B27: Historical financial analysis and forward-looking scenarios where data permits.
... B37: A final executive report with findings, limitations, and recommendations.

Sheet TESLA inc. HFP  
B2: TESLA, INC. Historical fiancial performance
B3: Company Analysis | Fiscal Years 2023–2025
L6: Tesla's total revenue declined 2.9% in 2025, from $97.69 billion to $94.83 billion. Automotive revenue fell 9.8%, while energy generation and storage revenue increased 26.6%. Tesla attributed the automotive sales decline primarily to approximately 8% fewer cash deliveries and a lower average selling price per vehicle, driven by sales mix and customer incentives. Energy growth was primarily supported by increased Megapack and Powerwall deployments. Profitability weakened considerably. Operating income fell 38.5%, from $7.08 billion to $4.36 billion, and the operating margin declined from 7.2% to 4.6%. Tesla's research and development expenses increased from $4.54 billion to $6.41 billion, contributing to higher operating expenses. Meanwhile, operating cash flow declined only 1.2%, to $14.75 billion, and capital expenditures decreased 24.8%, to $8.53 billion. Overall, the results show a shift in Tesla's growth mix toward energy storage, alongside pressure on automotive revenue and overall operating profitability. The next stage should examine segment gross margins, operating expense growth, and the company's planned investments to determine whether these trends are sustainable.
B9: Note: USD millions $
D10: 2025 | E10: 2024 | F10: 2023
H11: Revenue growth (YoY) | I11: operating margin
B12: Total revenue | D12: 94827 | E12: 97990 | F12: 96773 | H12: =(D12-E12)/E12 -> -0.032278804 | I12: =D15/D12 -> 0.045925738
B13: Automotive revenue | D13: 69526 | E13: 77070 | F13: 82419 | H13: =(D13/E13)-1 -> -0.09788504
B14: energy generation and storage revenue | D14: 12771 | E14: 10086 | F14: 6035 | H14: =(D14/E14)-1 -> 0.26621059
B15: operating income | D15: 4355 | E15: 7076 | F15: 8891 | H15: =(D15/E15)-1 -> -0.38453929
B16: net income | D16: 3855 | E16: 7153 | F16: 14974 | H16: =(D16/E16)-1 -> -0.46106529
B17: operating cashflow | D17: 14747 | E17: 14923 | F17: 13256 | H17: =(D17/E17)-1 -> -0.011793875
B18: capital expenditures | D18: 8527 | E18: 11342 | F18: 8899 | H18: =(D18/E18)-1 -> -0.24819256
A23: - | N23: source:
L26: Revenue Mix Analysis: Key Findings Tesla's revenue mix changed significantly between 2023 and 2025. Automotive revenue declined from $82.42 billion in 2023 to $69.53 billion in 2025, reducing its share of total revenue from approximately 85% to 73%. This indicates that Tesla's overall revenue has become less concentrated in automotive sales, although automotive remains its largest source of revenue. In contrast, energy generation and storage revenue more than doubled, increasing from $6.04 billion in 2023 to $12.77 billion in 2025. Its share of total revenue rose from approximately 6% to 13%. Services and other revenue also increased, from $8.32 billion to $12.53 billion, growing from approximately 9% to 13% of total revenue. Despite growth in energy and services, these increases did not fully offset the decline in automotive revenue. Total revenue decreased from $96.77 billion in 2023 to $94.83 billion in 2025. This suggests Tesla's expanding energy business is becoming increasingly important, but the company remains exposed to changes in automotive demand, pricing, and competition. The next step is to compare year-over-year growth across these revenue categories to determine how quickly each business is changing and whether growth in energy and services can continue to offset automotive weakness.
B32: Revenue Mix Analysis (USD Millions)
D33: 2025 | E33: 2024 | F33: 2023
B34: automotive revenue | D34: 69559 | E34: 77070 | F34: 82419
B35: energy generation and storage | D35: 12771 | E35: 10086 | F35: 6035
B36: services and other | D36: 12530 | E36: 10534 | F36: 8319
B37: total revenue | D37: 94827 | E37: 97690 | F37: 96773
B38: automotive % of total | D38: =D34/D37 -> 0.73353581 | E38: =E34/E37 -> 0.78892415 | F38: =F34/F37 -> 0.8516735
B39: energy % of total | D39: =D35/D37 -> 0.13467683 | E39: =E35/E37 -> 0.10324496 | F39: =F35/F37 -> 0.062362436
B40: services % of total | D40: =D36/D37 -> 0.13213536 | E40: =E36/E37 -> 0.10783089 | F40: =F36/F37 -> 0.08596406
N46: source:
L48: Year-over-Year Revenue Growth: Key Findings Tesla's revenue trends show a growing difference between its automotive business and its other revenue categories. Automotive revenue declined by approximately 9.8% in 2025, following a 6.5% decline in 2024. This marks two consecutive years of declining automotive revenue and highlights the company's exposure to vehicle demand, pricing, and competition. In contrast, energy generation and storage revenue increased by 26.6% in 2025, following growth of approximately 67.1% in 2024. Although the growth rate slowed, the segment continued expanding rapidly. Services and other revenue also grew, increasing by 18.9% in 2025 after rising 26.6% in 2024. Despite growth in energy and services, total revenue declined by 2.9% in 2025 after increasing by approximately 0.9% in 2024. This indicates that growth outside automotive has not yet fully offset the decline in automotive revenue. From a financial risk perspective, Tesla's expanding energy business provides greater revenue diversification, but continued weakness in automotive remains a significant concern. These trends warrant further investigation into segment profitability, operating expenses, and cash generation to determine whether growth in newer business areas can support Tesla's overall financial performance.
B55: Year over year Revenue growth
B56: Revenue category | C56: 2025 vs. 2024 | E56: 2024 vs 2023
B57: automotive revenue | C57: =(D34/E34)-1 -> -0.097456857 | E57: =(E34/F34)-1 -> -0.064900084
B58: energy generation and storage | C58: =(D35/E35)-1 -> 0.26621059 | E58: =(E35/F35)-1 -> 0.67125104
B59: services and other | C59: =(D36/E36)-1 -> 0.18948168 | E59: =(E36/F36)-1 -> 0.26625796
B60: total revenue | C60: =(D37/E37)-1 -> -0.029306992 | E60: =(E37/F37)-1 -> 0.0094757835
N68: source:
L73: Profitability Analysis: Tesla's profitability weakened significantly between 2023 and 2025. Gross profit remained relatively stable, declining from $17.66 billion in 2023 to $17.09 billion in 2025. However, gross margin stayed around 18% across all three years, suggesting that Tesla maintained a relatively consistent relationship between revenue and the direct costs of producing its products. Operating income declined from $8.89 billion in 2023 to $4.36 billion in 2025. As a result, operating margin fell from approximately 9% to 5%, indicating that Tesla generated less operating profit from each dollar of revenue. Net income also dropped sharply, from $14.97 billion in 2023 to $3.86 billion in 2025, reducing net profit margin from approximately 15% to 4%. The decline in operating and net income, despite relatively stable gross profit, suggests that costs below the gross profit line and changes in non-operating income and expenses played an important role in Tesla's reduced profitability. This raises concerns about the company's ability to maintain earnings as automotive revenue declines. The next step is to examine Tesla's operating expenses and cash flow to better understand what is driving the decline in profitability.
B80: Profitability analysis | D80: 2025 | E80: 2024 | F80: 2023
B82: gross profit | D82: 17094 | E82: 17450 | F82: 17660
B83: Gross margin | D83: =D82/D12 -> 0.18026511 | E83: =E82/E12 -> 0.1780794 | F83: =F82/F12 -> 0.18248892
B84: operating income | D84: 4355 | E84: 7076 | F84: 8891
B85: operating margin | D85: =D84/D12 -> 0.045925738 | E85: =E84/E12 -> 0.07221145 | F85: =F84/F12 -> 0.0918748
B86: net income | D86: =3855 -> 3855 | E86: 7153 | F86: 14974
...

Sheet tesla financial modeling 
J3: EBITDA Proxy Analysis: Tesla's EBITDA proxy declined from approximately $13.56 billion in 2023 to $10.50 billion in 2025. Its EBITDA proxy margin also decreased from approximately 14.0% to 11.1%, indicating that the company generated less operating earnings, before depreciation and amortization adjustments, for each dollar of revenue. This decline is consistent with the weaker operating performance identified in (tesla HFP sheet). Tesla's operating income fell from $8.89 billion in 2023 to $4.36 billion in 2025, while total revenue also declined. This suggests that the reduction in earnings was not caused by lower revenue alone; Tesla's ability to convert revenue into operating profit also weakened. From a financial analysis perspective, the declining EBITDA proxy margin raises questions about automotive pricing, production costs, operating expenses, and Tesla's ability to maintain profitability as its business mix changes. Growth in energy generation and storage may help offset weakness in automotive, but further analysis is needed to determine how these businesses contribute to earnings. Overall, the EBITDA proxy provides another indication that Tesla's operating performance weakened between 2023 and 2025. The next step is to examine operating expenses and other factors that contributed to this decline before using historical performance to build financial forecasts.
B9: EBITDA proxy
D10: 2025 | E10: 2024 | F10: 2023
B11: operating income | D11: 4355 | E11: ='TESLA inc. HFP '!E84 -> 7076 | F11: ='TESLA inc. HFP '!F84 -> 8891
B12: depreciation, amorization and impairment | D12: 6148 | E12: 6148 | F12: 6148
B13: EBITDA PROXY | D13: =D12+D11 -> 10503 | E13: =E12+E11 -> 13224 | F13: =F12+F11 -> 15039
B14: EBOTDA PROXY Margin | D14: =D13/'TESLA inc. HFP '!D12 -> 0.11075959 | E14: =E13/'TESLA inc. HFP '!E12 -> 0.13495255 | F14: =F13/'TESLA inc. HFP '!F12 -> 0.15540492
J22: Operating Expense Analysis: Key Findings Tesla's total operating expenses increased from $8.77 billion in 2023 to $12.74 billion in 2025. Operating expenses also rose from 9.1% of revenue in 2023 to 13.4% in 2025, meaning a larger share of Tesla's revenue was used to cover research, administration, and restructuring costs. Research and development was the largest driver of this increase. R&D expenses rose from $3.97 billion in 2023 to $6.41 billion in 2025, increasing by approximately 61%. Tesla reported that the 2025 increase was primarily related to AI and other programs, along with higher stock-based compensation. This spending may support future growth, but it also puts pressure on current profitability. Selling, general and administrative expenses increased from $4.80 billion to $5.83 billion over the same period. Tesla also recorded $684 million in restructuring expenses in 2024 and $494 million in 2025. These additional costs contributed to the overall operating expense burden. From a financial risk perspective, rising operating expenses combined with declining revenue create pressure on operating margins. Tesla's investment in AI and other technologies could generate future returns, but the financial benefit will depend on whether these investments produce enough additional revenue and profit to justify their cost. Overall, operating expenses have grown faster than revenue, helping explain why Tesla's operating income and margins weakened. The next step is to connect these findings to a financial forecast and evaluate how changes in revenue growth and expenses could affect future profitability.
B25: Operating expense analysis
D26: 2025 | E26: 2024 | F26: 2023
B27: R&D | D27: 6411 | E27: 4540 | F27: 3969
B28: SG&A | D28: 5834 | E28: 5150 | F28: 4800
B29: restructuring and other | D29: 494 | E29: 684 | F29: 0
B30: total operating expenses | D30: =SUM(D27:D29) -> 12739 | E30: =SUM(E27:E29) -> 10374 | F30: =SUM(F27:F29) -> 8769
B31: R&D / revenue | D31: =D27/'TESLA inc. HFP '!D12 -> 0.067607327 | E31: =E27/'TESLA inc. HFP '!E12 -> 0.046331258 | F31: =F27/'TESLA inc. HFP '!F12 -> 0.041013506
B32: SG&A / revenue | D32: =D28/'TESLA inc. HFP '!D12 -> 0.061522562 | E32: =E28/'TESLA inc. HFP '!E12 -> 0.052556383 | F32: =F28/'TESLA inc. HFP '!F12 -> 0.049600612
B33: total operating expenses / revenue | D33: =D30/'TESLA inc. HFP '!D12 -> 0.13433938 | E33: =E30/'TESLA inc. HFP '!E12 -> 0.10586795 | F33: =F30/'TESLA inc. HFP '!F12 -> 0.090614118
B42: Income statement ($millions)
D43: 2025 | E43: 2024 | F43: 2023
B44: total revenue | D44: 94827 | E44: 97690 | F44: 96773
B45: cost of revenue | D45: 77733 | E45: 80240 | F45: 79113
B46: gross profit | D46: 17094 | E46: 17450 | F46: 17660 | J46: Tesla's operating cash flow increased from $13.26 billion in 2023 to $14.75 billion in 2025, showing that the company maintained strong cash generation despite declining revenue and profitability. However, operating cash flow decreased slightly from 2024 to 2025, suggesting that cash generation has remained relatively stable rather than experiencing significant growth. Capital expenditures decreased from $11.34 billion in 2024 to $8.53 billion in 2025, a reduction of approximately 25%. This decline helped Tesla preserve more cash, although lower capital spending does not necessarily indicate improved operating performance. Future investment requirements for AI, manufacturing, and energy infrastructure could increase capital expenditures again. Free cash flow increased from $3.58 billion in 2024 to $6.22 billion in 2025, representing approximately 74% growth. This improvement was primarily driven by reduced capital expenditures rather than stronger operating cash flow. From a financial risk perspective, Tesla's positive free cash flow provides financial flexibility, but long-term sustainability will depend on improving profitability while funding future investments.
B47: R&D | D47: 6411 | E47: 4540 | F47: 3969
B48: SG&A | D48: 5834 | E48: 5150 | F48: 4800
B49: restructuring and other | D49: 494 | E49: 684 | F49: 0
B50: total operating expenses | D50: =SUM(D47:D49) -> 12739 | E50: =SUM(E47:E49) -> 10374 | F50: =SUM(F47:F49) -> 8769
B51: operating income | D51: =D46-D50 -> 4355 | E51: =E46-E50 -> 7076 | F51: =F46-F50 -> 8891
B52: interest income | D52: =1680 -> 1680 | E52: 1569 | F52: 1066
B53: interest expense | D53: =-338 -> -338 | E53: -350 | F53: -156
B54: other expense income, net | D54: -419 | E54: 695 | F54: 172
B55: income before taxes | D55: =SUM(D51:D54) -> 5278 | E55: =SUM(E51:E54) -> 8990 | F55: =SUM(F51:F54) -> 9973
B56: provision for income taxes | D56: 1423 | E56: 1837 | F56: -5001
B57: net income | D57: =D55-D56 -> 3855 | E57: =E55-E56 -> 7153 | F57: =F55-F56 -> 14974
B59: Balance sheet ($millions)
D60: 2025 | E60: 2024
B61: cash | D61: 16513 | E61: 16139
B62: short term investments | D62: 27546 | E62: 20424
B63: accounts receivvable | D63: 4576 | E63: 4418
B64: prepaid expenses and other CA | D64: 7615 | E64: 5362
B65: inventory | D65: 12392 | E65: 12017
...

Sheet TSLA forecastin & evaluation 
B3: revenue forcast
D4: 2025 actual | E4: 2026 forecast | F4: 2027 forecast | G4: 2028 forecast | H4: 2029 forecast | I4: 2030 forecast | L4: Tesla's total revenue is projected to increase from $94.83 billion in 2025 to approximately $141.27 billion by 2030, representing roughly 49% cumulative growth. This forecast assumes a gradual recovery in automotive revenue alongside continued expansion in energy generation and storage. Energy is expected to be one of Tesla's strongest growth drivers, with projected revenue increasing from $12.77 billion in 2025 to approximately $30.45 billion by 2030. Meanwhile, automotive revenue is projected to reach $87.75 billion, reflecting a more conservative recovery following recent declines. From a financial risk perspective, these projections depend on Tesla maintaining demand, managing competition, and successfully expanding its energy business. Actual performance could differ significantly from these assumptions, making scenario and sensitivity analysis important in later stages of the valuation.
B5: automotive | D5: =69526 -> 69526 | E5: =D5*(1+E13+$C$202) -> 69526 | F5: =E5*(1+F13+$C$202) -> 72307.04 | G5: =F5*(1+G13+$C$202) -> 76645.462 | H5: =G5*(1+H13+$C$202) -> 82010.645 | I5: =H5*(1+I13+$C$202) -> 87751.39
B6: energy generation & storage | D6: 12771 | E6: =D6*(1+E14+$C$202) -> 15325.2 | F6: =E6*(1+F14+$C$202) -> 18696.744 | G6: =F6*(1+G14+$C$202) -> 22436.093 | H6: =G6*(1+H14+$C$202) -> 26474.59 | I6: =H6*(1+I14+$C$202) -> 30445.778
B7: services and other | D7: 12530 | E7: =D7*(1+E15+$C$202) -> 14409.5 | F7: =E7*(1+F15+$C$202) -> 16570.925 | G7: =F7*(1+G15+$C$202) -> 18725.145 | H7: =G7*(1+H15+$C$202) -> 20972.163 | I7: =H7*(1+I15+$C$202) -> 23069.379
B8: total revenue | D8: =SUM(D5:D7) -> 94827 | E8: =SUM(E5:E7) -> 99260.7 | F8: =SUM(F5:F7) -> 107574.71 | G8: =SUM(G5:G7) -> 117806.7 | H8: =SUM(H5:H7) -> 129457.4 | I8: =SUM(I5:I7) -> 141266.55
B9: revenue growth % | E9: =(E8/D8)-1 -> 0.046755671 | F9: =(F8/E8)-1 -> 0.083759323 | G9: =(G8/F8)-1 -> 0.095115214 | H9: =(H8/G8)-1 -> 0.098896722 | I9: =(I8/H8)-1 -> 0.091220356
B11: revenue growth assumptions
D12: 2025 actual | E12: 2026 forecast | F12: 2027 forecast | G12: 2028 forecast | H12: 2029 forecast | I12: 2030 forecast
B13: automotive growth % | E13: 0 | F13: 0.04 | G13: 0.06 | H13: 0.07 | I13: 0.07
B14: energy growth | E14: 0.2 | F14: 0.22 | G14: 0.2 | H14: 0.18 | I14: 0.15
B15: services growth | E15: 0.15 | F15: 0.15 | G15: 0.13 | H15: 0.12 | I15: 0.1
L21: Profitability Forecast Analysis (2026–2030) Tesla's gross margin is projected to increase from 18.03% in 2025 to 23% by 2030. This forecast assumes that Tesla gradually improves manufacturing efficiency, benefits from economies of scale, and generates a larger share of revenue from its growing energy and services businesses. We assumed cost of revenue would decline from 81% of revenue in 2026 to 77% in 2030. These improvements are estimates rather than guaranteed outcomes, particularly given competition and potential pricing pressure in the automotive market. Research and development expenses are projected to remain relatively high, ranging from 7% of revenue in 2026 to 6.2% by 2030. This assumption reflects Tesla's continued investment in AI, autonomous driving, robotics, and energy technologies. Meanwhile, SG&A expenses are expected to decrease from 6% to 5.2% of revenue as the company grows and spreads administrative costs across a larger revenue base. Restructuring expenses are assumed to decline from $400 million in 2026 to $100 million in 2030, reflecting an expectation of fewer extraordinary restructuring costs. Under these assumptions, Tesla's operating income is projected to increase from $4.36 billion in 2025 to approximately $16.29 billion in 2030, with operating margins improving from 4.59% to 11.52%. This recovery depends heavily on revenue growth, cost control, and successful execution of Tesla's expansion strategy. From a financial risk perspective, weaker demand, higher production costs, or increased R&D spending could significantly reduce projected profitability. These assumptions will be tested later through scenario and sensitivity analysis.
B26: Profatibality forecast($millions)
D27: 2025 actual | E27: 2026 forecast | F27: 2027 forecast | G27: 2028 forecast | H27: 2029 forecast | I27: 2030 forecast
B28: total revenue | D28: 94827 | E28: =E8 -> 99260.7 | F28: =F8 -> 107574.71 | G28: =G8 -> 117806.7 | H28: =H8 -> 129457.4 | I28: =I8 -> 141266.55
B29: cost of revenue | D29: 77733 | E29: =E28*E41 -> 80401.167 | F29: =F28*F41 -> 86059.767 | G29: =G28*G41 -> 93067.293 | H29: =H28*H41 -> 100976.77 | I29: =I28*I41 -> 108775.24
B30: gross profit | D30: 17094 | E30: =E28-E29 -> 18859.533 | F30: =F28-F29 -> 21514.942 | G30: =G28-G29 -> 24739.407 | H30: =H28-H29 -> 28480.627 | I30: =I28-I29 -> 32491.306
B31: gross margin % | D31: =D30/D28 -> 0.18026511 | E31: =E30/E28 -> 0.19 | F31: =F30/F28 -> 0.2 | G31: =G30/G28 -> 0.21 | H31: =H30/H28 -> 0.22 | I31: =I30/I28 -> 0.23
B32: R&D expenses | D32: 6411 | E32: =E28*F42 -> 6948.249 | F32: =F28*G42 -> 7315.0802 | G32: =G28*H42 -> 7657.4355 | H32: =H28*I42 -> 8026.3586 | I32: =I28*I42 -> 8758.5259
B33: SG&A expenses | D33: 5834 | E33: =E28*E43 -> 5955.642 | F33: =F28*F43 -> 6239.3331 | G33: =G28*G43 -> 6597.1752 | H33: =H28*H43 -> 6990.6994 | I33: =I28*I43 -> 7345.8604
B34: restructuring and other | D34: 494 | E34: =E44 -> 400 | F34: =F44 -> 300 | G34: =G44 -> 200 | H34: =H44 -> 150 | I34: =I44 -> 100
B35: total operating expenses | D35: 12739 | E35: =SUM(E32:E34) -> 13303.891 | F35: =SUM(F32:F34) -> 13854.413 | G35: =SUM(G32:G34) -> 14454.611 | H35: =SUM(H32:H34) -> 15167.058 | I35: =SUM(I32:I34) -> 16204.386
B36: operating income | D36: 4355 | E36: =E30-E35+E28*$C$202 -> 5555.642 | F36: =F30-F35+F28*$C$202 -> 7660.5285 | G36: =G30-G35+G28*$C$202 -> 10284.796 | H36: =H30-H35+H28*$C$202 -> 13313.569 | I36: =I30-I35+I28*$C$202 -> 16286.919
B37: operating margin % | D37: =D36/D28 -> 0.045925738 | E37: =E36/E28 -> 0.055970208 | F37: =F36/F28 -> 0.07121124 | G37: =G36/G28 -> 0.087302304 | H37: =H36/H28 -> 0.10284132 | I37: =I36/I28 -> 0.11529212
B39: Profitability growth assumptions
D40: 2025 actual | E40: 2026 forecast | F40: 2027 forecast | G40: 2028 forecast | H40: 2029 forecast | I40: 2030 forecast
B41: cost of revenue % | E41: 0.81 | F41: 0.8 | G41: 0.79 | H41: 0.78 | I41: 0.77
B42: R&D % | E42: 0.07 | F42: 0.07 | G42: 0.068 | H42: 0.065 | I42: 0.062
B43: SG&A % | E43: 0.06 | F43: 0.058 | G43: 0.056 | H43: 0.054 | I43: 0.052
B44: restructuring (millions) | E44: 400 | F44: 300 | G44: 200 | H44: 150 | I44: 100
B50: net income forecast table
D51: 2025 actual | E51: 2026 forecast | F51: 2027 forecast | G51: 2028 forecast | H51: 2029 forecast | I51: 2030 forecast | L51: Tesla's net income is projected to increase from $3.86 billion in 2025 to approximately $12.93 billion by 2030, representing significant earnings growth over the forecast period. Net profit margin is expected to improve from 4.07% to 9.15%, driven primarily by higher revenue and improved operating efficiency. The forecast assumes gradually declining interest income, slightly increasing financing expenses, and a normalized effective tax rate of 25%. Other nonoperating income and expenses are assumed to be zero due to their unpredictable nature. Although the projections suggest a strong recovery in profitability, these results depend heavily on Tesla achieving its revenue growth targets and reducing operating costs as a percentage of revenue. Slower vehicle sales, increased competition, or higher operating expenses could materially reduce projected earnings.
B52: operating income | D52: =4355 -> 4355 | E52: =E36 -> 5555.642 | F52: =F36 -> 7660.5285 | G52: =G36 -> 10284.796 | H52: =H36 -> 13313.569 | I52: =I36 -> 16286.919
B53: interest income | D53: 1680 | E53: =E63 -> 1600 | F53: =F63 -> 1550 | G53: =G63 -> 1500 | H53: =H63 -> 1450 | I53: =I63 -> 1400
B54: interest expense | D54: -338 | E54: =E64 -> -350 | F54: =F64 -> -375 | G54: =G64 -> -400 | H54: =H64 -> -435 | I54: =I64 -> -450
B55: other income/expense | D55: -419 | E55: =E65 -> 0 | F55: =F65 -> 0 | G55: =G65 -> 0 | H55: =H65 -> 0 | I55: =I65 -> 0
B56: income before taxes | D56: 5278 | E56: =SUM(E52:E55) -> 6805.642 | F56: =SUM(F52:F55) -> 8835.5285 | G56: =SUM(G52:G55) -> 11384.796 | H56: =SUM(H52:H55) -> 14328.569 | I56: =SUM(I52:I55) -> 17236.919
B57: income tax expense | D57: 1423 | E57: =E56*E66 -> 1701.4105 | F57: =F56*F66 -> 2208.8821 | G57: =G56*G66 -> 2846.1991 | H57: =H56*H66 -> 3582.1423 | I57: =I56*I66 -> 4309.2299
B58: net income | D58: =D56-D57 -> 3855 | E58: =E56-E57 -> 5104.2315 | F58: =F56-F57 -> 6626.6463 | G58: =G56-G57 -> 8538.5973 | H58: =H56-H57 -> 10746.427 | I58: =I56-I57 -> 12927.69
...

Sheet TSLA scenario analysis 
B2: Scenario Summary
D3: Current Values: | E3: bear case | F3: base case | G3: bull case
E4: Created by M Anderson on 10/21/2026 | F4: Created by M Anderson on 10/21/2026 | G4: Created by M Anderson on 10/21/2026
B5: Changing Cells:
C6: $C$201 | D6: 0 | E6: -0.05 | F6: 0 | G6: 0.05
C7: $C$202 | D7: 0 | E7: -0.02 | F7: 0 | G7: 0.02
C8: $C$203 | D8: 0 | E8: 0.15 | F8: 0 | G8: -0.15
B9: Result Cells:
C10: $C$157 | D10: 79265.244 | E10: 48257.181 | F10: 79265.244 | G10: 114976.94
C11: $C$159 | D11: 21.123699 | E11: 12.860241 | F11: 21.123699 | G11: 30.640645
B12: Notes: Current Values column represents values of changing cells at
B13: time Scenario Summary Report was created. Changing cells for each
B14: scenario are highlighted in gray.

Sheet Financial Risk Assesment 
B2: Risk identification Matrix
B3: risk category | C3: primary risk | D3: financial impact | E3: likelyhood (1-5) | F3: imapact (1-5) | G3: Risk score | H3: Risk Level | M3: Tesla's financial risk assessment identifies profitability (20/25) as its highest risk, followed by revenue, capital expenditures, and valuation (16/25 each). Stress testing demonstrated significant operating leverage, with a 10% increase in operating costs resulting in negative operating income. Moderate cash flow stress also produced approximately $1.48 billion in negative free cash flow. Meanwhile, liquidity (6/25) and solvency (4/25) present relatively lower risks, supported by strong liquidity ratios and limited financial leverage. Overall, Tesla's primary modeled financial risks stem from profitability pressures and investment requirements rather than immediate balance sheet concerns. Risk scores reflect qualitative judgments based on hypothetical scenarios.
B4: revenue | C4: slower vehicle demand | D4: lower sales growth | E4: 4 | F4: 4 | G4: =E4*F4 -> 16 | H4: =IF(G4>=15,"High",IF(G4>=8,"Moderate","Low")) -> High
B5: profitability | C5: price competition | D5: margin compression | E5: 4 | F5: 5 | G5: =E5*F5 -> 20 | H5: =IF(G5>=15,"High",IF(G5>=8,"Moderate","Low")) -> High
B6: liquidity | C6: higher cash requirement | D6: reduced cash reserves | E6: 2 | F6: 3 | G6: =E6*F6 -> 6 | H6: =IF(G6>=15,"High",IF(G6>=8,"Moderate","Low")) -> Low
B7: solvency | C7: debt and fixed obligation | D7: reduced financial flexibility | E7: 2 | F7: 2 | G7: =E7*F7 -> 4 | H7: =IF(G7>=15,"High",IF(G7>=8,"Moderate","Low")) -> Low
B8: capex | C8: higher investment spending | D8: lower free cash flo w | E8: 4 | F8: 4 | G8: =E8*F8 -> 16 | H8: =IF(G8>=15,"High",IF(G8>=8,"Moderate","Low")) -> High
B9: valuation | C9: changes in wacc and growth | D9: lower intrinsic valuation | E9: 4 | F9: 4 | G9: =E9*F9 -> 16 | H9: =IF(G9>=15,"High",IF(G9>=8,"Moderate","Low")) -> High
B12: liquidity and solvency analysis | F12: Tesla's liquidity position improved from 2024 to 2025, with its current ratio increasing from 2.03 to 2.16 and its quick ratio rising from 1.42 to 1.53. This suggests the company has strengthened its ability to cover short-term obligations. Additionally, debt-to-equity declined from 11.3% to 10.2%, indicating relatively low financial leverage and reduced balance sheet risk. However, the operating cash flow ratio decreased from 0.52 to 0.47, suggesting weaker operating cash generation relative to current liabilities. Despite this decline, Tesla's free cash flow margin improved from 3.7% to 6.6%, reflecting lower capital expenditures rather than stronger operating performance. Overall, Tesla demonstrates a relatively strong liquidity position and limited debt exposure, although declining operating cash flow coverage remains an important risk to monitor.
C13: 2025 | D13: 2024
B14: current ratio | C14: ='tesla financial modeling '!D66/'tesla financial modeling '!D70 -> 2.1644069 | D14: ='tesla financial modeling '!E66/'tesla financial modeling '!E70 -> 2.0249124
B15: quick ratio | C15: =('tesla financial modeling '!D61+'tesla financial modeling '!D62+'tesla financial modeling '!D63)/'tesla financial modeling '!D70 -> 1.5335499 | D15: =('tesla financial modeling '!E61+'tesla financial modeling '!E62+'tesla financial modeling '!E63)/'tesla financial modeling '!E70 -> 1.4219146
B16: cash ratio | C16: =('tesla financial modeling '!D61+'tesla financial modeling '!D62)/'tesla financial modeling '!D70 -> 1.3892603 | D16: =('tesla financial modeling '!E61+'tesla financial modeling '!E62)/'tesla financial modeling '!E70 -> 1.2686236
B17: debt to equity | C17: ='tesla financial modeling '!D72/'tesla financial modeling '!D76 -> 0.10197597 | D17: ='tesla financial modeling '!E72/'tesla financial modeling '!E76 -> 0.11264109
B18: debt to asset | C18: ='tesla financial modeling '!D72/'tesla financial modeling '!D69 -> 0.060781098 | D18: ='tesla financial modeling '!E72/'tesla financial modeling '!E69 -> 0.067281068
B19: operating cash flow ratio | C19: ='tesla financial modeling '!D81/'tesla financial modeling '!D70 -> 0.46499968 | D19: ='tesla financial modeling '!E81/'tesla financial modeling '!E70 -> 0.51778217
B20: free cash flow margin | C20: ='tesla financial modeling '!D83/'tesla financial modeling '!D44 -> 0.065593133 | D20: ='tesla financial modeling '!E83/'tesla financial modeling '!E44 -> 0.036656771
B24: Revenue stress testing ($millions)
C25: base | D25: mild | E25: moderate | F25: severe | H25: Tesla's revenue stress test demonstrates significant sensitivity to declining sales. Under the assumed cost structure of 80% variable costs and 20% fixed costs, a 10% decline in projected 2026 revenue reduces operating income from $5.56 billion to $3.13 billion, representing a decline of approximately 44%. Under moderate stress, operating income falls to approximately $696 million, reducing operating margins from 5.60% to 0.88%. In the severe scenario, a 30% revenue decline results in an operating loss of approximately $1.73 billion. These findings suggest that Tesla's profitability is highly sensitive to revenue performance, particularly when fixed operating expenses remain unchanged. Although the results depend on hypothetical cost assumptions, they highlight the importance of revenue stability and cost flexibility in managing financial risk.
B26: revenue shock | C26: 0 | D26: -0.1 | E26: -0.2 | F26: -0.3
B27: 2026 revenue | C27: ='TSLA forecastin & evaluation '!E28 -> 99260.7 | D27: =$C$27*(1+D26) -> 89334.63 | E27: =$C$27*(1+E26) -> 79408.56 | F27: =$C$27*(1+F26) -> 69482.49
B28: operating income | C28: ='TSLA forecastin & evaluation '!E52 -> 5555.642 | D28: =D27-(($C$27-$C$28)*80%*(1+D26))-($C$27-$C$28)*20% -> 3125.9766 | E28: =E27-(($C$27-$C$28)*80%*(1+E26))-($C$27-$C$28)*20% -> 696.31128 | F28: =F27-(($C$27-$C$28)*80%*(1+F26))-($C$27-$C$28)*20% -> -1733.3541
B29: operating margin | C29: =C28/C27 -> 0.055970208 | D29: =D28/D27 -> 0.034991768 | E29: =E28/E27 -> 0.0087687181 | F29: =F28/F27 -> -0.024946632
B30: revenue change | C30: =C27-$C$27 -> 0 | D30: =D27-$C$27 -> -9926.07 | E30: =E27-$C$27 -> -19852.14 | F30: =F27-$C$27 -> -29778.21
B31: operating income change | C31: =C28-$C$28 -> 0 | D31: =D28-$C$28 -> -2429.6654 | E31: =E28-$C$28 -> -4859.3307 | F31: =F28-$C$28 -> -7288.9961
B38: margin & cost stress testing
C39: base | D39: mild | E39: moderate | F39: severe
B40: operating cost shock | C40: 0 | D40: 0.05 | E40: 0.1 | F40: 0.15 | H40: Tesla's margin and cost stress test highlights significant exposure to rising operating expenses. Holding projected 2026 revenue constant at $99.26 billion, a 5% increase in operating costs reduces operating income from $5.56 billion to approximately $870 million, representing an 84% decline. Under moderate stress, a 10% increase in operating costs results in an operating loss of approximately $3.81 billion. In the severe scenario, operating losses reach $8.50 billion, with operating margins falling to -8.56%. These findings demonstrate that Tesla's projected profitability is highly sensitive to cost inflation. While the scenarios are hypothetical, they emphasize the importance of controlling production expenses, maintaining pricing power, and improving operational efficiency.
B41: 2026 revenue | C41: =$C$27 -> 99260.7 | D41: =$C$27 -> 99260.7 | E41: =$C$27 -> 99260.7 | F41: =$C$27 -> 99260.7
B42: base operation cost | C42: =$C$27-$C$28 -> 93705.058 | D42: =$C$27-$C$28 -> 93705.058 | E42: =$C$27-$C$28 -> 93705.058 | F42: =$C$27-$C$28 -> 93705.058
B43: stressed operation cost | C43: =C42*(1+C40) -> 93705.058 | D43: =D42*(1+D40) -> 98390.311 | E43: =E42*(1+E40) -> 103075.56 | F43: =F42*(1+F40) -> 107760.82
B44: operating income | C44: =C41-C43 -> 5555.642 | D44: =D41-D43 -> 870.3891 | E44: =E41-E43 -> -3814.8638 | F44: =F41-F43 -> -8500.1167
B45: operating margin | C45: =C44/C41 -> 0.055970208 | D45: =D44/D41 -> 0.0087687181 | E45: =E44/E41 -> -0.038432771 | F45: =F44/F41 -> -0.085634261
B46: operating income change | C46: =C44-$C$28 -> 0 | D46: =D44-$C$28 -> -4685.2529 | E46: =E44-$C$28 -> -9370.5058 | F46: =F44-$C$28 -> -14055.759
B52: CF stress testing ($millions)
C53: base | D53: mild | E53: moderate | F53: severe | H53: Tesla's cash flow stress test highlights its sensitivity to declining operating cash flow and increasing capital expenditures. Under the mild scenario, projected 2026 free cash flow declines from $2.62 billion to approximately $574 million, representing a 78% reduction. Under moderate stress, free cash flow turns negative at approximately $1.48 billion, while the severe scenario produces negative free cash flow of $3.52 billion. These results suggest that Tesla's projected cash generation may be insufficient to support its planned capital expenditures during periods of financial pressure. Although Tesla maintains substantial liquidity reserves, sustained negative free cash flow could reduce financial flexibility and increase reliance on existing cash or external financing. These scenarios are hypothetical and demonstrate the importance of monitoring operating cash generation alongside future investment requirements.
B54: operating cost shock | C54: 0 | D54: -0.1 | E54: -0.2 | F54: -0.3
B55: capex increase | C55: 0 | D55: 0.05 | E55: 0.1 | F55: 0.15
B56: operating cash flow | C56: ='TSLA forecastin & evaluation '!E79 -> 14533.998 | D56: =$C$56*(1+D54) -> 13080.598 | E56: =$C$56*(1+E54) -> 11627.198 | F56: =$C$56*(1+F54) -> 10173.799
B57: capex | C57: ='TSLA forecastin & evaluation '!E80 -> 11911.284 | D57: =$C$57*(1+D55) -> 12506.848 | E57: =$C$57*(1+E55) -> 13102.412 | F57: =$C$57*(1+F55) -> 13697.977
...
